<?xml version="1.0"?>
<sdf version="1.4">

		<model name="road_runner">
			<pose>3.6 -0.5 1 0 0 1.5707963268</pose>
			<link name="rrTorso">
				<pose> 0 0 0.231   0 0 0</pose>
				<inertial>
					<mass>2.72</mass>
					<inertia>
						<ixx>1</ixx>
						<ixy>0</ixy>
						<ixz>0</ixz>
						<iyy>1</iyy>
						<iyz>0</iyz>
						<izz>1</izz>
					</inertia>
				</inertial>

				<visual name="visual">
          <geometry>
						<mesh><uri>file://rrTorso.stl</uri></mesh>
          </geometry>
        </visual>
				<collision name="collision">
					<geometry>
							  <mesh><uri>file://rrTorso.stl</uri></mesh>
					</geometry>
				</collision>

			</link>

			<link name="left_wheel">
				<pose> 0.088 0 0.231    0 0 0</pose>
				<inertial>
					<mass>0.5</mass>
					<inertia>
						<ixx>0.01334025</ixx>
						<ixy>0</ixy>
						<ixz>0</ixz>
						<iyy>0.006670125</iyy>
						<iyz>0</iyz>
						<izz>0.006670125</izz>
					</inertia>
				</inertial>
				<visual name="visual">
          <geometry>
						<mesh><uri>file://rrWheel.stl</uri></mesh>
          </geometry>
        </visual>
				<collision name="collision">
					<geometry>
							  <mesh><uri>file://rrWheel.stl</uri></mesh>
					</geometry>
				</collision>
			</link>

			<link name="right_wheel">
				<pose> -0.088 0 0.231    0 0 0</pose>
				<inertial>
					<mass>0.5</mass>
					<inertia>
						<ixx>0.01334025</ixx>
						<ixy>0</ixy>
						<ixz>0</ixz>
						<iyy>0.006670125</iyy>
						<iyz>0</iyz>
						<izz>0.006670125</izz>
					</inertia>
				</inertial>
				<visual name="visual">
          <geometry>
						<mesh><uri>file://rrWheel.stl</uri></mesh>
          </geometry>
        </visual>
				<collision name="collision">
					<geometry>
							  <mesh><uri>file://rrWheel.stl</uri></mesh>
					</geometry>
				</collision>
			</link>
			<joint name="right_bearing" type="revolute">
				<parent>rrTorso</parent>
				<child>right_wheel</child>
				<pose>0 0 0   0 0 0</pose>
				<axis>
					<xyz> 1 0 0</xyz>
				</axis>
				<sensor name="force_torque" type="force_torque">
						  <update_rate>30</update_rate>
				</sensor>
			</joint>
			<plugin name="actuator_plugin" filename="libActuatorPlugin.so">
				<actuator>                      
					<name>actuator_0</name>       
					<joint>right_bearing</joint>        
					<index>0</index>              
					<type>electric_motor</type>   
					<power>20</power>             
					<max_velocity>6</max_velocity>
					<max_torque>10.0</max_torque> 
				</actuator>                     
			</plugin>

			<joint name="left_bearing" type="revolute">
				<parent>rrTorso</parent>
				<child>left_wheel</child>
				<pose>0 0 0   0 0 0</pose>
				<axis>
					<xyz> 1 0 0</xyz>
				</axis>
				<sensor name="force_torque" type="force_torque">
						  <update_rate>30</update_rate>
				</sensor>
			</joint>
			<plugin name="actuator_plugin" filename="libActuatorPlugin.so">
				<actuator>                      
					<name>actuator_1</name>       
					<joint>left_bearing</joint>        
					<index>1</index>              
					<type>electric_motor</type>   
					<power>20</power>             
					<max_velocity>6</max_velocity>
					<max_torque>10.0</max_torque> 
				</actuator>                     
			</plugin>

			<plugin name="rrpush" filename="librrpush.dylib"/>

		</model>
</sdf>
